<!-- generated by Phobos -->
<robot name="yaro_1105" version="1.0">
  <joint name="joint_1" type="revolute">
    <limit lower="-3.1415926536" upper="3.1415926536" effort="194" velocity="4.189"/>
    <origin rpy="0.0000000000 0.0000000000 0.0000000000" xyz="0.0000000000 0.0000000000 0.1940000000"/>
    <parent link="link_0"/>
    <child link="link_1"/>
    <axis xyz="0.0000000000 0.0000000000 1.0000000000"/>
  </joint>
  <joint name="joint_2" type="revolute">
    <limit lower="-3.1415926536" upper="3.1415926536" effort="194" velocity="4.189"/>
    <origin rpy="-1.5707963268 0.0000000000 0.0000000000" xyz="0.0000000000 0.0820000000 0.1095000000"/>
    <parent link="link_1"/>
    <child link="link_2"/>
    <axis xyz="0.0000000000 0.0000000000 1.0000000000"/>
  </joint>
  <joint name="joint_3" type="revolute">
    <limit lower="-3.1415926536" upper="3.1415926536" effort="102" velocity="5.027"/>
    <origin rpy="-3.1415926536 0.0000000000 0.0000000000" xyz="0.0000000000 -0.4000000000 0.0000000000"/>
    <parent link="link_2"/>
    <child link="link_3"/>
    <axis xyz="0.0000000000 0.0000000000 1.0000000000"/>
  </joint>
  <joint name="joint_4" type="revolute">
    <limit lower="-3.1415926536" upper="3.1415926536" effort="34" velocity="8.16"/>
    <origin rpy="-1.5707963268 0.0000000000 0.0000000000" xyz="0.0000000000 0.1985000000 0.0820000000"/>
    <parent link="link_3"/>
    <child link="link_4"/>
    <axis xyz="0.0000000000 0.0000000000 1.0000000000"/>
  </joint>
  <joint name="joint_5" type="revolute">
    <limit lower="-3.1415926536" upper="3.1415926536" effort="34" velocity="8.16"/>
    <origin rpy="-1.5707963268 0.0000000000 0.0000000000" xyz="0.0000000000 -0.0788000000 0.2518000000"/>
    <parent link="link_4"/>
    <child link="link_5"/>
    <axis xyz="0.0000000000 0.0000000000 1.0000000000"/>
  </joint>
  <joint name="joint_6" type="revolute">
    <limit lower="-3.1415926536" upper="3.1415926536" effort="34" velocity="8.16"/>
    <origin rpy="1.5707963268 0.0000000000 0.0000000000" xyz="0.0000000000 -0.0642000000 0.0788000000"/>
    <parent link="link_5"/>
    <child link="link_6"/>
    <axis xyz="0.0000000000 0.0000000000 1.0000000000"/>
  </joint>
  <joint name="ee_frame_joint" type="fixed">
    <origin rpy="0.0000000000 0.0000000000 0.0000000000" xyz="-0.0000004213 0.0005324899 0.0805000000"/>
    <parent link="link_6"/>
    <child link="ee_frame"/>
  </joint>
  <link name="link_0">
    <collision name="collision_link_0">
      <origin rpy="0.0000000000 0.0000000000 0.0000000000" xyz="0.0000000000 0.0000000000 0.0000000000"/>
      <geometry>
        <mesh filename="../meshes/stl/link_0_yaro_1105.stl" scale="1.0000000000 1.0000000000 1.0000000000"/>
      </geometry>
    </collision>
    <inertial>
      <inertia ixx="0.0308961240" ixy="-0.0000086662" ixz="-0.0000814415" iyy="0.0307796818" iyz="0.0000907797" izz="0.0171736654"/>
      <origin rpy="0.0000000000 0.0000000000 0.0000000000" xyz="-0.0002480393 0.0000766940 0.1109493502"/>
      <mass value="6.5030297053"/>
    </inertial>
    <visual name="visual_link_0">
      <material name="0c416cff"/>
      <origin rpy="0.0000000000 0.0000000000 0.0000000000" xyz="0.0000000000 0.0000000000 0.0000000000"/>
      <geometry>
        <mesh filename="../meshes/stl/link_0_yaro_1105.stl" scale="1.0000000000 1.0000000000 1.0000000000"/>
      </geometry>
    </visual>
  </link>
  <link name="link_1">
    <collision name="collision_link_1">
      <origin rpy="0.0000000000 0.0000000000 0.0000000000" xyz="0.0000000000 0.0000000000 0.0000000000"/>
      <geometry>
        <mesh filename="../meshes/stl/link_1_yaro_1105.stl" scale="1.0000000000 1.0000000000 1.0000000000"/>
      </geometry>
    </collision>
    <inertial>
      <inertia ixx="0.0245298823" ixy="0.0000686921" ixz="-0.0000235438" iyy="0.0183485315" iyz="-0.0011272297" izz="0.0186154491"/>
      <origin rpy="0.0000000000 0.0000000000 0.0000000000" xyz="0.0001746829 0.0126683439 0.0940783716"/>
      <mass value="6.1821726893"/>
    </inertial>
    <visual name="visual_link_1">
      <material name="0c416cff"/>
      <origin rpy="0.0000000000 0.0000000000 0.0000000000" xyz="0.0000000000 0.0000000000 0.0000000000"/>
      <geometry>
        <mesh filename="../meshes/stl/link_1_yaro_1105.stl" scale="1.0000000000 1.0000000000 1.0000000000"/>
      </geometry>
    </visual>
  </link>
  <link name="link_2">
    <collision name="collision_link_2">
      <origin rpy="0.0000000000 0.0000000000 0.0000000000" xyz="0.0000000000 0.0000000000 0.0000000000"/>
      <geometry>
        <mesh filename="../meshes/stl/link_2_yaro_1105.stl" scale="1.0000000000 1.0000000000 1.0000000000"/>
      </geometry>
    </collision>
    <inertial>
      <inertia ixx="0.0951861980" ixy="-0.0000043287" ixz="0.0000000272" iyy="0.0084090309" iyz="0.0020302104" izz="0.0952068033"/>
      <origin rpy="0.0000000000 0.0000000000 0.0000000000" xyz="0.0000004503 -0.1686297033 0.0495512852"/>
      <mass value="3.0929093626"/>
    </inertial>
    <visual name="visual_link_2">
      <material name="e6e6e6ff"/>
      <origin rpy="0.0000000000 0.0000000000 0.0000000000" xyz="0.0000000000 0.0000000000 0.0000000000"/>
      <geometry>
        <mesh filename="../meshes/stl/link_2_yaro_1105.stl" scale="1.0000000000 1.0000000000 1.0000000000"/>
      </geometry>
    </visual>
  </link>
  <link name="link_3">
    <collision name="collision_link_3">
      <origin rpy="0.0000000000 0.0000000000 0.0000000000" xyz="0.0000000000 0.0000000000 0.0000000000"/>
      <geometry>
        <mesh filename="../meshes/stl/link_3_yaro_1105.stl" scale="1.0000000000 1.0000000000 1.0000000000"/>
      </geometry>
    </collision>
    <inertial>
      <inertia ixx="0.0372143489" ixy="-0.0000092250" ixz="0.0000287690" iyy="0.0110800117" iyz="-0.0038852101" izz="0.0321105886"/>
      <origin rpy="0.0000000000 0.0000000000 0.0000000000" xyz="-0.0001792108 0.0560750575 0.0679278715"/>
      <mass value="4.9616989026"/>
    </inertial>
    <visual name="visual_link_3">
      <material name="0c416cff"/>
      <origin rpy="0.0000000000 0.0000000000 0.0000000000" xyz="0.0000000000 0.0000000000 0.0000000000"/>
      <geometry>
        <mesh filename="../meshes/stl/link_3_yaro_1105.stl" scale="1.0000000000 1.0000000000 1.0000000000"/>
      </geometry>
    </visual>
  </link>
  <link name="link_4">
    <collision name="collision_link_4">
      <origin rpy="0.0000000000 0.0000000000 0.0000000000" xyz="0.0000000000 0.0000000000 0.0000000000"/>
      <geometry>
        <mesh filename="../meshes/stl/link_4_yaro_1105.stl" scale="1.0000000000 1.0000000000 1.0000000000"/>
      </geometry>
    </collision>
    <inertial>
      <inertia ixx="0.0409559951" ixy="0.0000309741" ixz="-0.0000302639" iyy="0.0309510940" iyz="0.0137450994" izz="0.0140641314"/>
      <origin rpy="0.0000000000 0.0000000000 0.0000000000" xyz="0.0001597202 -0.1010749250 0.1796152628"/>
      <mass value="2.9529725266"/>
    </inertial>
    <visual name="visual_link_4">
      <material name="eaeaeaff"/>
      <origin rpy="0.0000000000 0.0000000000 0.0000000000" xyz="0.0000000000 0.0000000000 0.0000000000"/>
      <geometry>
        <mesh filename="../meshes/stl/link_4_yaro_1105.stl" scale="1.0000000000 1.0000000000 1.0000000000"/>
      </geometry>
    </visual>
  </link>
  <link name="link_5">
    <collision name="collision_link_5">
      <origin rpy="0.0000000000 0.0000000000 0.0000000000" xyz="0.0000000000 0.0000000000 0.0000000000"/>
      <geometry>
        <mesh filename="../meshes/stl/link_5_yaro_1105.stl" scale="1.0000000000 1.0000000000 1.0000000000"/>
      </geometry>
    </collision>
    <inertial>
      <inertia ixx="0.0054243063" ixy="0.0000177054" ixz="0.0000079309" iyy="0.0032677986" iyz="0.0000567393" izz="0.0042877501"/>
      <origin rpy="0.0000000000 0.0000000000 0.0000000000" xyz="-0.0002010296 -0.0029940509 0.0663166882"/>
      <mass value="2.1607588730"/>
    </inertial>
    <visual name="visual_link_5">
      <material name="0c416cff"/>
      <origin rpy="0.0000000000 0.0000000000 0.0000000000" xyz="0.0000000000 0.0000000000 0.0000000000"/>
      <geometry>
        <mesh filename="../meshes/stl/link_5_yaro_1105.stl" scale="1.0000000000 1.0000000000 1.0000000000"/>
      </geometry>
    </visual>
  </link>
  <link name="link_6">
    <collision name="collision_link_6">
      <origin rpy="0.0000000000 0.0000000000 0.0000000000" xyz="0.0000000000 0.0000000000 0.0000000000"/>
      <geometry>
        <mesh filename="../meshes/stl/link_6_yaro_1105.stl" scale="1.0000000000 1.0000000000 1.0000000000"/>
      </geometry>
    </collision>
    <inertial>
      <inertia ixx="0.0008311842" ixy="-0.0000152868" ixz="0.0000035044" iyy="0.0008358232" iyz="-0.0000105417" izz="0.0007965315"/>
      <origin rpy="0.0000000000 0.0000000000 0.0000000000" xyz="0.0002719535 0.0003153301 0.0377232275"/>
      <mass value="0.7008202987"/>
    </inertial>
    <visual name="visual_link_6">
      <material name="999999ff"/>
      <origin rpy="0.0000000000 0.0000000000 0.0000000000" xyz="0.0000000000 0.0000000000 0.0000000000"/>
      <geometry>
        <mesh filename="../meshes/stl/link_6_yaro_1105.stl" scale="1.0000000000 1.0000000000 1.0000000000"/>
      </geometry>
    </visual>
  </link>
  <link name="ee_frame"/>
  <material name="0c416cff">
    <color rgba="0.0470588235 0.2549019608 0.4235294118 1.0000000000"/>
  </material>
  <material name="999999ff">
    <color rgba="0.6000000000 0.6000000000 0.6000000000 1.0000000000"/>
  </material>
  <material name="e6e6e6ff">
    <color rgba="0.9019607843 0.9019607843 0.9019607843 1.0000000000"/>
  </material>
  <material name="eaeaeaff">
    <color rgba="0.9176470588 0.9176470588 0.9176470588 1.0000000000"/>
  </material>
</robot>