<!-- generated by Phobos -->
<robot name="yaro_1105" version="1.0">
  <joint name="joint_1" type="revolute">
    <limit lower="-6.28318531" upper="6.28318531" effort="194.00000000" velocity="4.18879020"/>
    <origin rpy="0.00000000 0.00000000 0.00000000" xyz="0.00000000 0.00000000 0.19400000"/>
    <parent link="link_0"/>
    <child link="link_1"/>
    <axis xyz="0.00000000 0.00000000 1.00000000"/>
  </joint>
  <joint name="joint_2" type="revolute">
    <limit lower="-6.28318531" upper="6.28318531" effort="194.00000000" velocity="4.18879020"/>
    <origin rpy="-1.57079633 0.00000000 0.00000000" xyz="0.00000000 0.08200000 0.10950000"/>
    <parent link="link_1"/>
    <child link="link_2"/>
    <axis xyz="0.00000000 0.00000000 1.00000000"/>
  </joint>
  <joint name="joint_3" type="revolute">
    <limit lower="-2.79252680" upper="2.79252680" effort="102.00000000" velocity="8.37758041"/>
    <origin rpy="3.14159265 0.00000000 0.00000000" xyz="0.00000000 -0.49000000 0.00000000"/>
    <parent link="link_2"/>
    <child link="link_3"/>
    <axis xyz="0.00000000 0.00000000 1.00000000"/>
  </joint>
  <joint name="joint_4" type="revolute">
    <limit lower="-6.28318531" upper="6.28318531" effort="34.00000000" velocity="7.33038286"/>
    <origin rpy="-1.57079633 0.00000000 0.00000000" xyz="0.00000000 0.19850000 0.08200000"/>
    <parent link="link_3"/>
    <child link="link_4"/>
    <axis xyz="0.00000000 0.00000000 1.00000000"/>
  </joint>
  <joint name="joint_5" type="revolute">
    <limit lower="-2.26892798" upper="2.26892798" effort="34.00000000" velocity="7.33038286"/>
    <origin rpy="-1.57079633 0.00000000 0.00000000" xyz="0.00000000 -0.07880000 0.27180000"/>
    <parent link="link_4"/>
    <child link="link_5"/>
    <axis xyz="0.00000000 0.00000000 1.00000000"/>
  </joint>
  <joint name="joint_6" type="revolute">
    <limit lower="-6.28318531" upper="6.28318531" effort="34.00000000" velocity="7.33038286"/>
    <origin rpy="1.57079633 0.00000000 0.00000000" xyz="0.00000000 -0.06420000 0.07880000"/>
    <parent link="link_5"/>
    <child link="link_6"/>
    <axis xyz="0.00000000 0.00000000 1.00000000"/>
  </joint>
  <joint name="ee_frame_joint" type="fixed">
    <origin rpy="0.00000000 0.00000000 0.00000000" xyz="-0.00000042 0.00053249 0.08050000"/>
    <parent link="link_6"/>
    <child link="ee_frame"/>
  </joint>
  <link name="link_0">
    <collision name="collision_link_0">
      <origin rpy="0.00000000 0.00000000 0.00000000" xyz="0.00000000 0.00000000 0.00000000"/>
      <geometry>
        <mesh filename="../meshes/stl/link_0_yaro_1105.stl" scale="1.00000000 1.00000000 1.00000000"/>
      </geometry>
    </collision>
    <inertial>
      <inertia ixx="0.03144433" ixy="-0.00000881" ixz="-0.00008329" iyy="0.03132855" iyz="0.00009524" izz="0.01737448"/>
      <origin rpy="0.00000000 0.00000000 0.00000000" xyz="-0.00024723 0.00008572 0.11160789"/>
      <mass value="6.57443822"/>
    </inertial>
    <visual name="visual_link_0">
      <material name="0c416cff"/>
      <origin rpy="0.00000000 0.00000000 0.00000000" xyz="0.00000000 0.00000000 0.00000000"/>
      <geometry>
        <mesh filename="../meshes/stl/link_0_yaro_1105.stl" scale="1.00000000 1.00000000 1.00000000"/>
      </geometry>
    </visual>
  </link>
  <link name="link_1">
    <collision name="collision_link_1">
      <origin rpy="0.00000000 0.00000000 0.00000000" xyz="0.00000000 0.00000000 0.00000000"/>
      <geometry>
        <mesh filename="../meshes/stl/link_1_yaro_1105.stl" scale="1.00000000 1.00000000 1.00000000"/>
      </geometry>
    </collision>
    <inertial>
      <inertia ixx="0.02522749" ixy="0.00006762" ixz="-0.00002347" iyy="0.01878474" iyz="-0.00120463" izz="0.01919394"/>
      <origin rpy="0.00000000 0.00000000 0.00000000" xyz="0.00016873 0.01322259 0.09403804"/>
      <mass value="6.27832178"/>
    </inertial>
    <visual name="visual_link_1">
      <material name="0c416cff"/>
      <origin rpy="0.00000000 0.00000000 0.00000000" xyz="0.00000000 0.00000000 0.00000000"/>
      <geometry>
        <mesh filename="../meshes/stl/link_1_yaro_1105.stl" scale="1.00000000 1.00000000 1.00000000"/>
      </geometry>
    </visual>
  </link>
  <link name="link_2">
    <collision name="collision_link_2">
      <origin rpy="0.00000000 0.00000000 0.00000000" xyz="0.00000000 0.00000000 0.00000000"/>
      <geometry>
        <mesh filename="../meshes/stl/link_2_yaro_1105.stl" scale="1.00000000 1.00000000 1.00000000"/>
      </geometry>
    </collision>
    <inertial>
      <inertia ixx="0.14692608" ixy="-0.00000411" ixz="0.00000003" iyy="0.00914487" iyz="0.00264987" izz="0.14712550"/>
      <origin rpy="0.00000000 0.00000000 0.00000000" xyz="0.00000032 -0.21005149 0.05064607"/>
      <mass value="3.44377444"/>
    </inertial>
    <visual name="visual_link_2">
      <material name="e6e6e6ff"/>
      <origin rpy="0.00000000 0.00000000 0.00000000" xyz="0.00000000 0.00000000 0.00000000"/>
      <geometry>
        <mesh filename="../meshes/stl/link_2_yaro_1105.stl" scale="1.00000000 1.00000000 1.00000000"/>
      </geometry>
    </visual>
  </link>
  <link name="link_3">
    <collision name="collision_link_3">
      <origin rpy="0.00000000 0.00000000 0.00000000" xyz="0.00000000 0.00000000 0.00000000"/>
      <geometry>
        <mesh filename="../meshes/stl/link_3_yaro_1105.stl" scale="1.00000000 1.00000000 1.00000000"/>
      </geometry>
    </collision>
    <inertial>
      <inertia ixx="0.03908001" ixy="-0.00001075" ixz="0.00002936" iyy="0.01149368" iyz="-0.00417208" izz="0.03378216"/>
      <origin rpy="0.00000000 0.00000000 0.00000000" xyz="-0.00017574 0.05747560 0.06762882"/>
      <mass value="5.08297766"/>
    </inertial>
    <visual name="visual_link_3">
      <material name="0c416cff"/>
      <origin rpy="0.00000000 0.00000000 0.00000000" xyz="0.00000000 0.00000000 0.00000000"/>
      <geometry>
        <mesh filename="../meshes/stl/link_3_yaro_1105.stl" scale="1.00000000 1.00000000 1.00000000"/>
      </geometry>
    </visual>
  </link>
  <link name="link_4">
    <collision name="collision_link_4">
      <origin rpy="0.00000000 0.00000000 0.00000000" xyz="0.00000000 0.00000000 0.00000000"/>
      <geometry>
        <mesh filename="../meshes/stl/link_4_yaro_1105.stl" scale="1.00000000 1.00000000 1.00000000"/>
      </geometry>
    </collision>
    <inertial>
      <inertia ixx="0.04745501" ixy="0.00003061" ixz="-0.00003310" iyy="0.03727700" iyz="0.01525868" izz="0.01438207"/>
      <origin rpy="0.00000000 0.00000000 0.00000000" xyz="0.00015525 -0.10080603 0.19208715"/>
      <mass value="3.04194742"/>
    </inertial>
    <visual name="visual_link_4">
      <material name="eaeaeaff"/>
      <origin rpy="0.00000000 0.00000000 0.00000000" xyz="0.00000000 0.00000000 0.00000000"/>
      <geometry>
        <mesh filename="../meshes/stl/link_4_yaro_1105.stl" scale="1.00000000 1.00000000 1.00000000"/>
      </geometry>
    </visual>
  </link>
  <link name="link_5">
    <collision name="collision_link_5">
      <origin rpy="0.00000000 0.00000000 0.00000000" xyz="0.00000000 0.00000000 0.00000000"/>
      <geometry>
        <mesh filename="../meshes/stl/link_5_yaro_1105.stl" scale="1.00000000 1.00000000 1.00000000"/>
      </geometry>
    </collision>
    <inertial>
      <inertia ixx="0.00560217" ixy="0.00001789" ixz="0.00000797" iyy="0.00335805" iyz="0.00006735" izz="0.00442283"/>
      <origin rpy="0.00000000 0.00000000 0.00000000" xyz="-0.00019752 -0.00340357 0.06611734"/>
      <mass value="2.19975282"/>
    </inertial>
    <visual name="visual_link_5">
      <material name="0c416cff"/>
      <origin rpy="0.00000000 0.00000000 0.00000000" xyz="0.00000000 0.00000000 0.00000000"/>
      <geometry>
        <mesh filename="../meshes/stl/link_5_yaro_1105.stl" scale="1.00000000 1.00000000 1.00000000"/>
      </geometry>
    </visual>
  </link>
  <link name="link_6">
    <collision name="collision_link_6">
      <origin rpy="0.00000000 0.00000000 0.00000000" xyz="0.00000000 0.00000000 0.00000000"/>
      <geometry>
        <mesh filename="../meshes/stl/link_6_yaro_1105.stl" scale="1.00000000 1.00000000 1.00000000"/>
      </geometry>
    </collision>
    <inertial>
      <inertia ixx="0.00085473" ixy="-0.00001528" ixz="0.00000342" iyy="0.00085895" iyz="-0.00001025" izz="0.00081969"/>
      <origin rpy="0.00000000 0.00000000 0.00000000" xyz="0.00026599 0.00033585 0.03727920"/>
      <mass value="0.71652484"/>
    </inertial>
    <visual name="visual_link_6">
      <material name="999999ff"/>
      <origin rpy="0.00000000 0.00000000 0.00000000" xyz="0.00000000 0.00000000 0.00000000"/>
      <geometry>
        <mesh filename="../meshes/stl/link_6_yaro_1105.stl" scale="1.00000000 1.00000000 1.00000000"/>
      </geometry>
    </visual>
  </link>
  <link name="ee_frame"/>
  <material name="0c416cff">
    <color rgba="0.04313725 0.25490196 0.42352941 1.00000000"/>
  </material>
  <material name="999999ff">
    <color rgba="0.60000000 0.60000000 0.60000000 1.00000000"/>
  </material>
  <material name="e6e6e6ff">
    <color rgba="0.89803922 0.89803922 0.89803922 1.00000000"/>
  </material>
  <material name="eaeaeaff">
    <color rgba="0.91372549 0.91372549 0.91372549 1.00000000"/>
  </material>
</robot>
